<robot name="TwoWheeledInvertedPendulum">

  <material name="blue">
    <color rgba="0.2 0.2 0.8 1"/>
  </material>
  <material name="black">
    <color rgba="0.15 0.15 0.15 1"/>
  </material>

  <link name="chassis">
    <inertial>
      <origin xyz="0 0 0.11" rpy="0 0 0"/>
      <mass value="1.0"/>
      <inertia ixx="0.00354" ixy="0" ixz="0" iyy="0.00417" iyz="0" izz="0.00104"/>
    </inertial>
    <visual>
      <origin xyz="0 0 0.11" rpy="0 0 0"/>
      <geometry>
        <box size="0.1 0.05 0.2"/> </geometry>
      <material name="blue"/>
    </visual>
    <collision>
      <origin xyz="0 0 0.11" rpy="0 0 0"/>
      <geometry>
        <box size="0.1 0.05 0.2"/>
      </geometry>
    </collision>
  </link>

  <link name="left_wheel">
    <inertial>
      <origin xyz="0 0 0" rpy="0 0 0"/>
      <mass value="0.2"/>
      <inertia ixx="0.0001316" ixy="0" ixz="0" iyy="0.00025" iyz="0" izz="0.0001316"/>
    </inertial>
    <visual>
      <origin xyz="0 0 0" rpy="1.57079632679 0 0"/> <geometry>
        <cylinder radius="0.05" length="0.02"/>
      </geometry>
      <material name="black"/>
    </visual>
    <collision>
      <origin xyz="0 0 0" rpy="1.57079632679 0 0"/>
      <geometry>
        <cylinder radius="0.05" length="0.02"/>
      </geometry>
    </collision>
  </link>

  <link name="right_wheel">
    <inertial>
      <origin xyz="0 0 0" rpy="0 0 0"/>
      <mass value="0.2"/>
      <inertia ixx="0.0001316" ixy="0" ixz="0" iyy="0.00025" iyz="0" izz="0.0001316"/>
    </inertial>
    <visual>
      <origin xyz="0 0 0" rpy="1.57079632679 0 0"/>
      <geometry>
        <cylinder radius="0.05" length="0.02"/>
      </geometry>
      <material name="black"/>
    </visual>
    <collision>
      <origin xyz="0 0 0" rpy="1.57079632679 0 0"/>
      <geometry>
        <cylinder radius="0.05" length="0.02"/>
      </geometry>
    </collision>
  </link>

  <joint name="left_wheel_joint" type="continuous">
    <parent link="chassis"/>
    <child link="left_wheel"/>
    <origin xyz="0 0.035 0" rpy="0 0 0"/> <axis xyz="0 1 0"/> </joint>

  <joint name="right_wheel_joint" type="continuous">
    <parent link="chassis"/>
    <child link="right_wheel"/>
    <origin xyz="0 -0.035 0" rpy="0 0 0"/> <axis xyz="0 1 0"/> </joint>

</robot>